Workbook

Sheet Produk_Master
A1: SKU | B1: Nama_Produk | C1: Kategori | D1: Gaya_90an | E1: Ukuran | F1: Kondisi | G1: Tipe_Pasokan | H1: Supplier_ID | I1: Modal_Unit_Rp | J1: Harga_Jual_Rp | K1: Safety_Stock_Unit | L1: Lead_Time_Target_Hari | M1: Margin_Kotor_%
A2: V90-TEE-001 | B2: Kaos Graphic Grunge | C2: Kaos | D2: Grunge / Band Tee | E2: M | F2: Vintage Grade A | G2: Restockable | H2: SUP-002 | I2: 42000 | J2: 89900 | K2: 5 | L2: 7 | M2: =IFERROR((J2-I2)/J2,0) -> 0.53281424
A3: V90-TEE-002 | B3: Kaos Washed Boxy | C3: Kaos | D3: Washed / Boxy Fit | E3: L | F3: New - 90s Style | G3: Restockable | H3: SUP-002 | I3: 38000 | J3: 79900 | K3: 6 | L3: 6 | M3: =IFERROR((J3-I3)/J3,0) -> 0.52440551
A4: V90-TEE-003 | B4: Raglan Baseball Tee | C4: Kaos | D4: Baseball / Raglan | E4: L | F4: Vintage Grade A | G4: Restockable | H4: SUP-001 | I4: 45000 | J4: 95000 | K4: 4 | L4: 8 | M4: =IFERROR((J4-I4)/J4,0) -> 0.52631579
A5: V90-FLN-001 | B5: Kemeja Flanel Kotak | C5: Kemeja | D5: Grunge Layering | E5: L | F5: Preloved Grade A | G5: Restockable | H5: SUP-004 | I5: 52000 | J5: 109000 | K5: 4 | L5: 8 | M5: =IFERROR((J5-I5)/J5,0) -> 0.52293578
A6: V90-DNM-001 | B6: Jaket Denim Oversize | C6: Jaket | D6: Denim / Oversize | E6: XL | F6: Preloved Grade A | G6: One-off Vintage | H6: SUP-003 | I6: 95000 | J6: 189000 | K6: 0 | L6: 0 | M6: =IFERROR((J6-I6)/J6,0) -> 0.4973545
A7: V90-WND-001 | B7: Windbreaker Colorblock | C7: Jaket | D7: Sporty Colorblock | E7: L | F7: Vintage Grade B | G7: One-off Vintage | H7: SUP-005 | I7: 78000 | J7: 159000 | K7: 0 | L7: 0 | M7: =IFERROR((J7-I7)/J7,0) -> 0.50943396
A8: V90-SWT-001 | B8: Crewneck Colorblock | C8: Sweater | D8: Colorblock | E8: L | F8: Preloved Grade A | G8: Restockable | H8: SUP-006 | I8: 68000 | J8: 139000 | K8: 3 | L8: 10 | M8: =IFERROR((J8-I8)/J8,0) -> 0.51079137
A9: V90-SWT-002 | B9: Sweater Stripe Retro | C9: Sweater | D9: Stripe / Retro | E9: M | F9: Preloved Grade A | G9: One-off Vintage | H9: SUP-001 | I9: 72000 | J9: 145000 | K9: 0 | L9: 0 | M9: =IFERROR((J9-I9)/J9,0) -> 0.50344828
A10: V90-JNS-001 | B10: Jeans Straight Denim | C10: Celana | D10: Straight / Denim | E10: 32 | F10: Preloved Grade A | G10: Restockable | H10: SUP-003 | I10: 82000 | J10: 169000 | K10: 3 | L10: 9 | M10: =IFERROR((J10-I10)/J10,0) -> 0.5147929
A11: V90-CGO-001 | B11: Celana Cargo 90s | C11: Celana | D11: Cargo / Utility | E11: 32 | F11: New - 90s Style | G11: Restockable | H11: SUP-002 | I11: 76000 | J11: 159000 | K11: 4 | L11: 7 | M11: =IFERROR((J11-I11)/J11,0) -> 0.52201258
A12: V90-VST-001 | B12: Vest Knit Retro | C12: Outerwear | D12: Knit / Layering | E12: M | F12: Preloved Grade A | G12: One-off Vintage | H12: SUP-006 | I12: 48000 | J12: 99000 | K12: 0 | L12: 0 | M12: =IFERROR((J12-I12)/J12,0) -> 0.51515152
A13: V90-HDY-001 | B13: Hoodie Zip Vintage | C13: Hoodie | D13: Zip / Minimal | E13: XL | F13: Vintage Grade A | G13: Restockable | H13: SUP-001 | I13: 85000 | J13: 179000 | K13: 3 | L13: 10 | M13: =IFERROR((J13-I13)/J13,0) -> 0.52513966
... A16: V90-TRK-001 | B16: Track Jacket Retro | C16: Jaket | D16: Athletic / Colorblock | E16: L | F16: Preloved Grade A | G16: Restockable | H16: SUP-005 | I16: 88000 | J16: 179000 | K16: 3 | L16: 10 | M16: =IFERROR((J16-I16)/J16,0) -> 0.50837989

Sheet Pemasok
A1: Supplier_ID | B1: Nama_Pemasok | C1: Jenis_Sumber | D1: Kota | E1: Lead_Time_Target_Hari | F1: MOQ_Unit | G1: Tingkat_Cacat_Historis_% | H1: Rating_Internal_5
A2: SUP-001 | B2: Garasi Vintage Supply | C2: Thrift bundle & curated | D2: Bandung | E2: 8 | F2: 12 | G2: 0.07 | H2: 4.5
A3: SUP-002 | B3: Studio Washed Apparel | C3: Produksi ulang gaya 90-an | D3: Tangerang | E3: 6 | F3: 24 | G3: 0.025 | H3: 4.7
A4: SUP-003 | B4: Denim Rewear Hub | C4: Denim preloved | D4: Jakarta | E4: 9 | F4: 8 | G4: 0.06 | H4: 4.2
A5: SUP-004 | B5: Flanel Archive | C5: Kemeja preloved | D5: Bandung | E5: 8 | F5: 10 | G5: 0.045 | H5: 4.4
A6: SUP-005 | B6: Retro Outerwear Select | C6: Outerwear vintage | D6: Depok | E6: 10 | F6: 6 | G6: 0.055 | H6: 4.3
A7: SUP-006 | B7: Knit Revival | C7: Knitwear & vest | D7: Solo | E7: 10 | F7: 8 | G7: 0.04 | H7: 4.1

Sheet Pembelian
A1: PO_ID | B1: Tanggal_PO | C1: Tanggal_Terima | D1: Supplier_ID | E1: SKU | F1: Qty_Dipesan | G1: Qty_Diterima | H1: Modal_Unit_Rp | I1: Lead_Time_Aktual_Hari | J1: Qty_Rusak | K1: Total_Pembelian_Rp
A2: PO-0001 | B2: 46301 | C2: 46304 | D2: SUP-002 | E2: V90-TEE-001 | F2: 4 | G2: 4 | H2: 42000 | I2: =IF(C2="","",C2-B2) -> 3 | J2: 0 | K2: =G2*H2 -> 168000
A3: PO-0002 | B3: 46287 | C3: 46295 | D3: SUP-002 | E3: V90-TEE-001 | F3: 2 | G3: 2 | H3: 42000 | I3: =IF(C3="","",C3-B3) -> 8 | J3: 0 | K3: =G3*H3 -> 84000
A4: PO-0003 | B4: 46291 | C4: 46299 | D4: SUP-002 | E4: V90-TEE-001 | F4: 3 | G4: 3 | H4: 42000 | I4: =IF(C4="","",C4-B4) -> 8 | J4: 0 | K4: =G4*H4 -> 126000
A5: PO-0004 | B5: 46288 | C5: 46298 | D5: SUP-002 | E5: V90-TEE-002 | F5: 4 | G5: 4 | H5: 38000 | I5: =IF(C5="","",C5-B5) -> 10 | J5: 0 | K5: =G5*H5 -> 152000
A6: PO-0005 | B6: 46292 | C6: 46299 | D6: SUP-002 | E6: V90-TEE-002 | F6: 2 | G6: 2 | H6: 38000 | I6: =IF(C6="","",C6-B6) -> 7 | J6: 0 | K6: =G6*H6 -> 76000
A7: PO-0006 | B7: 46296 | C7: 46303 | D7: SUP-001 | E7: V90-TEE-003 | F7: 6 | G7: 6 | H7: 45000 | I7: =IF(C7="","",C7-B7) -> 7 | J7: 0 | K7: =G7*H7 -> 270000
A8: PO-0007 | B8: 46297 | C8: 46303 | D8: SUP-001 | E8: V90-TEE-003 | F8: 3 | G8: 3 | H8: 45000 | I8: =IF(C8="","",C8-B8) -> 6 | J8: 0 | K8: =G8*H8 -> 135000
A9: PO-0008 | B9: 46308 | C9: 46315 | D9: SUP-001 | E9: V90-TEE-003 | F9: 2 | G9: 2 | H9: 45000 | I9: =IF(C9="","",C9-B9) -> 7 | J9: 0 | K9: =G9*H9 -> 90000
A10: PO-0009 | B10: 46288 | C10: 46296 | D10: SUP-004 | E10: V90-FLN-001 | F10: 18 | G10: 18 | H10: 52000 | I10: =IF(C10="","",C10-B10) -> 8 | J10: 0 | K10: =G10*H10 -> 936000
A11: PO-0010 | B11: 46243 | C11: 46254 | D11: SUP-003 | E11: V90-DNM-001 | F11: 2 | G11: 2 | H11: 95000 | I11: =IF(C11="","",C11-B11) -> 11 | J11: 0 | K11: =G11*H11 -> 190000
A12: PO-0011 | B12: 46239 | C12: 46250 | D12: SUP-005 | E12: V90-WND-001 | F12: 9 | G12: 9 | H12: 78000 | I12: =IF(C12="","",C12-B12) -> 11 | J12: 0 | K12: =G12*H12 -> 702000
A13: PO-0012 | B13: 46303 | C13: 46314 | D13: SUP-006 | E13: V90-SWT-001 | F13: 15 | G13: 15 | H13: 68000 | I13: =IF(C13="","",C13-B13) -> 11 | J13: 0 | K13: =G13*H13 -> 1020000
... A27: PO-0026 | B27: 46299 | C27: 46307 | D27: SUP-005 | E27: V90-TRK-001 | F27: 2 | G27: 2 | H27: 88000 | I27: =IF(C27="","",C27-B27) -> 8 | J27: 0 | K27: =G27*H27 -> 176000

Sheet Pesanan
A1: Item_Order_ID | B1: Order_ID | C1: Tanggal_Order | D1: SKU | E1: Qty | F1: Harga_Jual_Unit_Rp | G1: Diskon_Rp | H1: Estimasi_Fee_Platform_Rp | I1: Status_Order | J1: Provinsi_Pembeli | K1: Kurir | L1: Tanggal_Dikirim | M1: Tanggal_Diterima | N1: Hari_Order_ke_Kirim | O1: Omzet_Kotor_Rp | P1: Omzet_Neto_Estimasi_Rp | Q1: HPP_Estimasi_Rp | R1: Margin_Estimasi_Rp
A2: OI-0001 | B2: SPX-2026501 | C2: 46288 | D2: V90-TEE-002 | E2: 1 | F2: 79900 | G2: 0 | H2: 7191 | I2: Terkirim | J2: Jawa Timur | K2: JNE | L2: 46289 | M2: 46294 | N2: =IF(L2="","",L2-C2) -> 1 | O2: =E2*F2 -> 79900 | P2: =O2-G2-H2 -> 72709 | Q2: =E2*VLOOKUP(D2,Produk_Master!$A$2:$I$16,9,FALSE) -> 38000 | R2: =P2-Q2 -> 34709
A3: OI-0002 | B3: SPX-2026789 | C3: 46288 | D3: V90-TEE-003 | E3: 1 | F3: 95000 | G3: 5000 | H3: 7600 | I3: Terkirim | J3: Sumatera Utara | K3: JNE | L3: 46289 | M3: 46290 | N3: =IF(L3="","",L3-C3) -> 1 | O3: =E3*F3 -> 95000 | P3: =O3-G3-H3 -> 82400 | Q3: =E3*VLOOKUP(D3,Produk_Master!$A$2:$I$16,9,FALSE) -> 45000 | R3: =P3-Q3 -> 37400
A4: OI-0003 | B4: SPX-2026678 | C4: 46287 | D4: V90-SWT-001 | E4: 1 | F4: 139000 | G4: 0 | H4: 9730 | I4: Dibatalkan | J4: Jawa Timur | K4: SiCepat | N4: =IF(L4="","",L4-C4) | O4: =E4*F4 -> 139000 | P4: =O4-G4-H4 -> 129270 | Q4: =E4*VLOOKUP(D4,Produk_Master!$A$2:$I$16,9,FALSE) -> 68000 | R4: =P4-Q4 -> 61270
A5: OI-0004 | B5: SPX-2026446 | C5: 46286 | D5: V90-DNM-001 | E5: 1 | F5: 189000 | G5: 5000 | H5: 13230 | I5: Dibatalkan | J5: Jawa Tengah | K5: SiCepat | N5: =IF(L5="","",L5-C5) | O5: =E5*F5 -> 189000 | P5: =O5-G5-H5 -> 170770 | Q5: =E5*VLOOKUP(D5,Produk_Master!$A$2:$I$16,9,FALSE) -> 95000 | R5: =P5-Q5 -> 75770
A6: OI-0005 | B6: SPX-2026618 | C6: 46315 | D6: V90-SWT-001 | E6: 1 | F6: 139000 | G6: 0 | H6: 12510 | I6: Terkirim | J6: Bali | K6: JNE | L6: 46317 | M6: 46320 | N6: =IF(L6="","",L6-C6) -> 2 | O6: =E6*F6 -> 139000 | P6: =O6-G6-H6 -> 126490 | Q6: =E6*VLOOKUP(D6,Produk_Master!$A$2:$I$16,9,FALSE) -> 68000 | R6: =P6-Q6 -> 58490
A7: OI-0006 | B7: SPX-2026570 | C7: 46300 | D7: V90-FLN-001 | E7: 2 | F7: 109000 | G7: 0 | H7: 21800 | I7: Terkirim | J7: Sumatera Utara | K7: SPX Express | L7: 46302 | M7: 46303 | N7: =IF(L7="","",L7-C7) -> 2 | O7: =E7*F7 -> 218000 | P7: =O7-G7-H7 -> 196200 | Q7: =E7*VLOOKUP(D7,Produk_Master!$A$2:$I$16,9,FALSE) -> 104000 | R7: =P7-Q7 -> 92200
A8: OI-0007 | B8: SPX-2026413 | C8: 46299 | D8: V90-CGO-001 | E8: 2 | F8: 159000 | G8: 5000 | H8: 22260 | I8: Terkirim | J8: Banten | K8: JNE | L8: 46299 | M8: 46302 | N8: =IF(L8="","",L8-C8) -> 0 | O8: =E8*F8 -> 318000 | P8: =O8-G8-H8 -> 290740 | Q8: =E8*VLOOKUP(D8,Produk_Master!$A$2:$I$16,9,FALSE) -> 152000 | R8: =P8-Q8 -> 138740
A9: OI-0008 | B9: SPX-2026183 | C9: 46289 | D9: V90-SWT-001 | E9: 1 | F9: 139000 | G9: 8000 | H9: 11120 | I9: Terkirim | J9: Banten | K9: SiCepat | L9: 46291 | M9: 46294 | N9: =IF(L9="","",L9-C9) -> 2 | O9: =E9*F9 -> 139000 | P9: =O9-G9-H9 -> 119880 | Q9: =E9*VLOOKUP(D9,Produk_Master!$A$2:$I$16,9,FALSE) -> 68000 | R9: =P9-Q9 -> 51880
A10: OI-0009 | B10: SPX-2026125 | C10: 46295 | D10: V90-JNS-001 | E10: 1 | F10: 169000 | G10: 3000 | H10: 11830 | I10: Terkirim | J10: DKI Jakarta | K10: JNE | L10: 46296 | M10: 46301 | N10: =IF(L10="","",L10-C10) -> 1 | O10: =E10*F10 -> 169000 | P10: =O10-G10-H10 -> 154170 | Q10: =E10*VLOOKUP(D10,Produk_Master!$A$2:$I$16,9,FALSE) -> 82000 | R10: =P10-Q10 -> 72170
A11: OI-0010 | B11: SPX-2026322 | C11: 46307 | D11: V90-JNS-001 | E11: 1 | F11: 169000 | G11: 3000 | H11: 11830 | I11: Terkirim | J11: DKI Jakarta | K11: SiCepat | L11: 46309 | M11: 46313 | N11: =IF(L11="","",L11-C11) -> 2 | O11: =E11*F11 -> 169000 | P11: =O11-G11-H11 -> 154170 | Q11: =E11*VLOOKUP(D11,Produk_Master!$A$2:$I$16,9,FALSE) -> 82000 | R11: =P11-Q11 -> 72170
A12: OI-0011 | B12: SPX-2026560 | C12: 46314 | D12: V90-JNS-001 | E12: 1 | F12: 169000 | G12: 0 | H12: 11830 | I12: Terkirim | J12: Sumatera Utara | K12: J&T | L12: 46316 | M12: 46318 | N12: =IF(L12="","",L12-C12) -> 2 | O12: =E12*F12 -> 169000 | P12: =O12-G12-H12 -> 157170 | Q12: =E12*VLOOKUP(D12,Produk_Master!$A$2:$I$16,9,FALSE) -> 82000 | R12: =P12-Q12 -> 75170
A13: OI-0012 | B13: SPX-2026169 | C13: 46297 | D13: V90-TEE-001 | E13: 2 | F13: 89900 | G13: 3000 | H13: 12586 | I13: Retur | J13: Banten | K13: SPX Express | L13: 46298 | M13: 46300 | N13: =IF(L13="","",L13-C13) -> 1 | O13: =E13*F13 -> 179800 | P13: =O13-G13-H13 -> 164214 | Q13: =E13*VLOOKUP(D13,Produk_Master!$A$2:$I$16,9,FALSE) -> 84000 | R13: =P13-Q13 -> 80214
A14: OI-0013 | B14: SPX-2026482 | C14: 46313 | D14: V90-SWT-001 | E14: 1 | F14: 139000 | G14: 3000 | H14: 12510 | I14: Terkirim | J14: Sumatera Utara | K14: SiCepat | L14: 46315 | M14: 46316 | N14: =IF(L14="","",L14-C14) -> 2 | O14: =E14*F14 -> 139000 | P14: =O14-G14-H14 -> 123490 | Q14: =E14*VLOOKUP(D14,Produk_Master!$A$2:$I$16,9,FALSE) -> 68000 | R14: =P14-Q14 -> 55490
A15: OI-0014 | B15: SPX-2026664 | C15: 46293 | D15: V90-TEE-002 | E15: 1 | F15: 79900 | G15: 3000 | H15: 5593 | I15: Retur | J15: DI Yogyakarta | K15: AnterAja | L15: 46295 | M15: 46297 | N15: =IF(L15="","",L15-C15) -> 2 | O15: =E15*F15 -> 79900 | P15: =O15-G15-H15 -> 71307 | Q15: =E15*VLOOKUP(D15,Produk_Master!$A$2:$I$16,9,FALSE) -> 38000 | R15: =P15-Q15 -> 33307
A16: OI-0015 | B16: SPX-2026875 | C16: 46298 | D16: V90-TEE-003 | E16: 2 | F16: 95000 | G16: 8000 | H16: 15200 | I16: Terkirim | J16: Banten | K16: JNE | L16: 46299 | M16: 46302 | N16: =IF(L16="","",L16-C16) -> 1 | O16: =E16*F16 -> 190000 | P16: =O16-G16-H16 -> 166800 | Q16: =E16*VLOOKUP(D16,Produk_Master!$A$2:$I$16,9,FALSE) -> 90000 | R16: =P16-Q16 -> 76800
A17: OI-0016 | B17: SPX-2026741 | C17: 46294 | D17: V90-CDG-001 | E17: 1 | F17: 115000 | G17: 0 | H17: 10350 | I17: Terkirim | J17: DKI Jakarta | K17: SiCepat | L17: 46294 | M17: 46295 | N17: =IF(L17="","",L17-C17) -> 0 | O17: =E17*F17 -> 115000 | P17: =O17-G17-H17 -> 104650 | Q17: =E17*VLOOKUP(D17,Produk_Master!$A$2:$I$16,9,FALSE) -> 55000 | R17: =P17-Q17 -> 49650
... A19: OI-0018 | B19: SPX-2026325 | C19: 46297 | D19: V90-FLN-001 | E19: 1 | F19: 109000 | G19: 8000 | H19: 9810 | I19: Terkirim | J19: DKI Jakarta | K19: J&T | L19: 46298 | M19: 46301 | N19: =IF(L19="","",L19-C19) -> 1 | O19: =E19*F19 -> 109000 | P19: =O19-G19-H19 -> 91190 | Q19: =E19*VLOOKUP(D19,Produk_Master!$A$2:$I$16,9,FALSE) -> 52000 | R19: =P19-Q19 -> 39190
A20: OI-0019 | B20: SPX-2026601 | C20: 46302 | D20: V90-SWT-002 | E20: 1 | F20: 145000 | G20: 3000 | H20: 11600 | I20: Dibatalkan | J20: Sumatera Utara | K20: JNE | N20: =IF(L20="","",L20-C20) | O20: =E20*F20 -> 145000 | P20: =O20-G20-H20 -> 130400 | Q20: =E20*VLOOKUP(D20,Produk_Master!$A$2:$I$16,9,FALSE) -> 72000 | R20: =P20-Q20 -> 58400
A21: OI-0020 | B21: SPX-2026289 | C21: 46296 | D21: V90-SWT-001 | E21: 1 | F21: 139000 | G21: 3000 | H21: 12510 | I21: Terkirim | J21: DI Yogyakarta | K21: AnterAja | L21: 46296 | M21: 46297 | N21: =IF(L21="","",L21-C21) -> 0 | O21: =E21*F21 -> 139000 | P21: =O21-G21-H21 -> 123490 | Q21: =E21*VLOOKUP(D21,Produk_Master!$A$2:$I$16,9,FALSE) -> 68000 | R21: =P21-Q21 -> 55490
A22: OI-0021 | B22: SPX-2026003 | C22: 46299 | D22: V90-TEE-002 | E22: 1 | F22: 79900 | G22: 5000 | H22: 5593 | I22: Terkirim | J22: Sumatera Utara | K22: AnterAja | L22: 46299 | M22: 46302 | N22: =IF(L22="","",L22-C22) -> 0 | O22: =E22*F22 -> 79900 | P22: =O22-G22-H22 -> 69307 | Q22: =E22*VLOOKUP(D22,Produk_Master!$A$2:$I$16,9,FALSE) -> 38000 | R22: =P22-Q22 -> 31307
A23: OI-0022 | B23: SPX-2026216 | C23: 46312 | D23: V90-FLN-001 | E23: 1 | F23: 109000 | G23: 0 | H23: 8720 | I23: Terkirim | J23: Banten | K23: JNE | L23: 46314 | M23: 46316 | N23: =IF(L23="","",L23-C23) -> 2 | O23: =E23*F23 -> 109000 | P23: =O23-G23-H23 -> 100280 | Q23: =E23*VLOOKUP(D23,Produk_Master!$A$2:$I$16,9,FALSE) -> 52000 | R23: =P23-Q23 -> 48280
A24: OI-0023 | B24: SPX-2026552 | C24: 46298 | D24: V90-SRT-001 | E24: 1 | F24: 99000 | G24: 8000 | H24: 7920 | I24: Terkirim | J24: Jawa Tengah | K24: JNE | L24: 46298 | M24: 46300 | N24: =IF(L24="","",L24-C24) -> 0 | O24: =E24*F24 -> 99000 | P24: =O24-G24-H24 -> 83080 | Q24: =E24*VLOOKUP(D24,Produk_Master!$A$2:$I$16,9,FALSE) -> 46000 | R24: =P24-Q24 -> 37080
A25: OI-0024 | B25: SPX-2026052 | C25: 46294 | D25: V90-TEE-002 | E25: 1 | F25: 79900 | G25: 0 | H25: 7191 | I25: Terkirim | J25: Jawa Barat | K25: SPX Express | L25: 46296 | M25: 46297 | N25: =IF(L25="","",L25-C25) -> 2 | O25: =E25*F25 -> 79900 | P25: =O25-G25-H25 -> 72709 | Q25: =E25*VLOOKUP(D25,Produk_Master!$A$2:$I$16,9,FALSE) -> 38000 | R25: =P25-Q25 -> 34709
A26: OI-0025 | B26: SPX-2026720 | C26: 46314 | D26: V90-TRK-001 | E26: 1 | F26: 179000 | G26: 5000 | H26: 14320 | I26: Terkirim | J26: DI Yogyakarta | K26: SPX Express | L26: 46315 | M26: 46316 | N26: =IF(L26="","",L26-C26) -> 1 | O26: =E26*F26 -> 179000 | P26: =O26-G26-H26 -> 159680 | Q26: =E26*VLOOKUP(D26,Produk_Master!$A$2:$I$16,9,FALSE) -> 88000 | R26: =P26-Q26 -> 71680
A27: OI-0026 | B27: SPX-2026285 | C27: 46306 | D27: V90-TRK-001 | E27: 1 | F27: 179000 | G27: 0 | H27: 17900 | I27: Terkirim | J27: DKI Jakarta | K27: J&T | L27: 46307 | M27: 46309 | N27: =IF(L27="","",L27-C27) -> 1 | O27: =E27*F27 -> 179000 | P27: =O27-G27-H27 -> 161100 | Q27: =E27*VLOOKUP(D27,Produk_Master!$A$2:$I$16,9,FALSE) -> 88000 | R27: =P27-Q27 -> 73100
A28: OI-0027 | B28: SPX-2026452 | C28: 46290 | D28: V90-SWT-001 | E28: 1 | F28: 139000 | G28: 8000 | H28: 9730 | I28: Terkirim | J28: DKI Jakarta | K28: J&T | L28: 46291 | M28: 46292 | N28: =IF(L28="","",L28-C28) -> 1 | O28: =E28*F28 -> 139000 | P28: =O28-G28-H28 -> 121270 | Q28: =E28*VLOOKUP(D28,Produk_Master!$A$2:$I$16,9,FALSE) -> 68000 | R28: =P28-Q28 -> 53270
A29: OI-0028 | B29: SPX-2026960 | C29: 46312 | D29: V90-SWT-002 | E29: 1 | F29: 145000 | G29: 0 | H29: 13050 | I29: Terkirim | J29: Banten | K29: JNE | L29: 46313 | M29: 46317 | N29: =IF(L29="","",L29-C29) -> 1 | O29: =E29*F29 -> 145000 | P29: =O29-G29-H29 -> 131950 | Q29: =E29*VLOOKUP(D29,Produk_Master!$A$2:$I$16,9,FALSE) -> 72000 | R29: =P29-Q29 -> 59950
A30: OI-0029 | B30: SPX-2026558 | C30: 46310 | D30: V90-CGO-001 | E30: 1 | F30: 159000 | G30: 3000 | H30: 11130 | I30: Diproses | J30: DI Yogyakarta | K30: JNE | N30: =IF(L30="","",L30-C30) | O30: =E30*F30 -> 159000 | P30: =O30-G30-H30 -> 144870 | Q30: =E30*VLOOKUP(D30,Produk_Master!$A$2:$I$16,9,FALSE) -> 76000 | R30: =P30-Q30 -> 68870
A31: OI-0030 | B31: SPX-2026572 | C31: 46308 | D31: V90-FLN-001 | E31: 2 | F31: 109000 | G31: 5000 | H31: 19620 | I31: Terkirim | J31: Jawa Tengah | K31: J&T | L31: 46309 | M31: 46310 | N31: =IF(L31="","",L31-C31) -> 1 | O31: =E31*F31 -> 218000 | P31: =O31-G31-H31 -> 193380 | Q31: =E31*VLOOKUP(D31,Produk_Master!$A$2:$I$16,9,FALSE) -> 104000 | R31: =P31-Q31 -> 89380
A32: OI-0031 | B32: SPX-2026035 | C32: 46315 | D32: V90-JNS-001 | E32: 2 | F32: 169000 | G32: 0 | H32: 33800 | I32: Terkirim | J32: Jawa Tengah | K32: SiCepat | L32: 46317 | M32: 46322 | N32: =IF(L32="","",L32-C32) -> 2 | O32: =E32*F32 -> 338000 | P32: =O32-G32-H32 -> 304200 | Q32: =E32*VLOOKUP(D32,Produk_Master!$A$2:$I$16,9,FALSE) -> 164000 | R32: =P32-Q32 -> 140200
A33: OI-0032 | B33: SPX-2026264 | C33: 46291 | D33: V90-CDG-001 | E33: 1 | F33: 115000 | G33: 3000 | H33: 8050 | I33: Terkirim | J33: Bali | K33: JNE | L33: 46292 | M33: 46293 | N33: =IF(L33="","",L33-C33) -> 1 | O33: =E33*F33 -> 115000 | P33: =O33-G33-H33 -> 103950 | Q33: =E33*VLOOKUP(D33,Produk_Master!$A$2:$I$16,9,FALSE) -> 55000 | R33: =P33-Q33 -> 48950
A34: OI-0033 | B34: SPX-2026866 | C34: 46296 | D34: V90-TEE-002 | E34: 1 | F34: 79900 | G34: 0 | H34: 6392 | I34: Terkirim | J34: DKI Jakarta | K34: J&T | L34: 46298 | M34: 46300 | N34: =IF(L34="","",L34-C34) -> 2 | O34: =E34*F34 -> 79900 | P34: =O34-G34-H34 -> 73508 | Q34: =E34*VLOOKUP(D34,Produk_Master!$A$2:$I$16,9,FALSE) -> 38000 | R34: =P34-Q34 -> 35508
A35: OI-0034 | B35: SPX-2026752 | C35: 46310 | D35: V90-CGO-001 | E35: 1 | F35: 159000 | G35: 8000 | H35: 11130 | I35: Terkirim | J35: Jawa Barat | K35: SPX Express | L35: 46310 | M35: 46312 | N35: =IF(L35="","",L35-C35) -> 0 | O35: =E35*F35 -> 159000 | P35: =O35-G35-H35 -> 139870 | Q35: =E35*VLOOKUP(D35,Produk_Master!$A$2:$I$16,9,FALSE) -> 76000 | R35: =P35-Q35 -> 63870
A36: OI-0035 | B36: SPX-2026351 | C36: 46305 | D36: V90-SRT-001 | E36: 1 | F36: 99000 | G36: 0 | H36: 8910 | I36: Terkirim | J36: Bali | K36: J&T | L36: 46305 | M36: 46308 | N36: =IF(L36="","",L36-C36) -> 0 | O36: =E36*F36 -> 99000 | P36: =O36-G36-H36 -> 90090 | Q36: =E36*VLOOKUP(D36,Produk_Master!$A$2:$I$16,9,FALSE) -> 46000 | R36: =P36-Q36 -> 44090
A37: OI-0036 | B37: SPX-2026635 | C37: 46305 | D37: V90-SWT-001 | E37: 1 | F37: 139000 | G37: 3000 | H37: 13900 | I37: Terkirim | J37: Jawa Tengah | K37: AnterAja | L37: 46307 | M37: 46309 | N37: =IF(L37="","",L37-C37) -> 2 | O37: =E37*F37 -> 139000 | P37: =O37-G37-H37 -> 122100 | Q37: =E37*VLOOKUP(D37,Produk_Master!$A$2:$I$16,9,FALSE) -> 68000 | R37: =P37-Q37 -> 54100
A38: OI-0037 | B38: SPX-2026679 | C38: 46303 | D38: V90-TEE-003 | E38: 1 | F38: 95000 | G38: 5000 | H38: 7600 | I38: Terkirim | J38: DKI Jakarta | K38: JNE | L38: 46305 | M38: 46308 | N38: =IF(L38="","",L38-C38) -> 2 | O38: =E38*F38 -> 95000 | P38: =O38-G38-H38 -> 82400 | Q38: =E38*VLOOKUP(D38,Produk_Master!$A$2:$I$16,9,FALSE) -> 45000 | R38: =P38-Q38 -> 37400
A39: OI-0038 | B39: SPX-2026292 | C39: 46287 | D39: V90-TEE-001 | E39: 1 | F39: 89900 | G39: 0 | H39: 8091 | I39: Diproses | J39: DKI Jakarta | K39: J&T | L39: 46287 | N39: =IF(L39="","",L39-C39) -> 0 | O39: =E39*F39 -> 89900 | P39: =O39-G39-H39 -> 81809 | Q39: =E39*VLOOKUP(D39,Produk_Master!$A$2:$I$16,9,FALSE) -> 42000 | R39: =P39-Q39 -> 39809
A40: OI-0039 | B40: SPX-2026299 | C40: 46292 | D40: V90-SWT-001 | E40: 2 | F40: 139000 | G40: 3000 | H40: 19460 | I40: Terkirim | J40: DI Yogyakarta | K40: SiCepat | L40: 46293 | M40: 46294 | N40: =IF(L40="","",L40-C40) -> 1 | O40: =E40*F40 -> 278000 | P40: =O40-G40-H40 -> 255540 | Q40: =E40*VLOOKUP(D40,Produk_Master!$A$2:$I$16,9,FALSE) -> 136000 | R40: =P40-Q40 -> 119540
A41: OI-0040 | B41: SPX-2026527 | C41: 46312 | D41: V90-TRK-001 | E41: 2 | F41: 179000 | G41: 8000 | H41: 35800 | I41: Diproses | J41: Banten | K41: JNE | L41: 46313 | N41: =IF(L41="","",L41-C41) -> 1 | O41: =E41*F41 -> 358000 | P41: =O41-G41-H41 -> 314200 | Q41: =E41*VLOOKUP(D41,Produk_Master!$A$2:$I$16,9,FALSE) -> 176000 | R41: =P41-Q41 -> 138200
...

Sheet Retur
A1: Return_ID | B1: Item_Order_ID | C1: SKU | D1: Qty_Retur | E1: Alasan_Retur | F1: Hasil_QC | G1: Nilai_Refund_Rp | H1: Tanggal_Retur
A2: RT-001 | B2: OI-0048 | C2: V90-TEE-003 | D2: 1 | E2: Warna berbeda dari ekspektasi | F2: Layak jual | G2: 95000 | H2: 46326
A3: RT-002 | B3: OI-0068 | C3: V90-TEE-003 | D3: 2 | E3: Ada noda setelah QC | F3: Tidak layak jual | G3: 190000 | H3: 46303
A4: RT-003 | B4: OI-0014 | C4: V90-TEE-002 | D4: 1 | E4: Salah pilih produk | F4: Layak jual | G4: 76900 | H4: 46305
A5: RT-004 | B5: OI-0075 | C5: V90-FLN-001 | D5: 1 | E5: Kondisi tidak sesuai deskripsi | F5: Tidak layak jual | G5: 109000 | H5: 46306
A6: RT-005 | B6: OI-0012 | C6: V90-TEE-001 | D6: 2 | E6: Ada noda setelah QC | F6: Tidak layak jual | G6: 176800 | H6: 46306

Sheet Persediaan
A1: SKU | B1: Nama_Produk | C1: Tipe_Pasokan | D1: Stok_Awal_01Sep | E1: Qty_Masuk_Period | F1: Qty_Terjual_Terkirim | G1: Qty_Retur_Layak_Jual | H1: Penyesuaian_Unit | I1: Stok_Akhir | J1: Safety_Stock_Unit | K1: Lead_Time_Target_Hari | L1: Demand_Rata2_30d_Unit_per_Hari | M1: Reorder_Point_Unit | N1: Status_Stok
A2: V90-TEE-001 | B2: Kaos Graphic Grunge | C2: Restockable | D2: 2 | E2: =SUMIFS(Pembelian!$G$2:$G$27,Pembelian!$E$2:$E$27,A2,Pembelian!$C$2:$C$27,">="&DATE(2026,9,1),Pembelian!$C$2:$C$27,"<="&DATE(2026,10,20))-SUMIFS(Pembelian!$J$2:$J$27,Pembelian!$E$2:$E$27,A2,Pembelian!$C$2:$C$27,">="&DATE(2026,9,1),Pembelian!$C$2:$C$27,"<="&DATE(2026,10,20)) -> 9 | F2: =SUMIFS(Pesanan!$E$2:$E$87,Pesanan!$D$2:$D$87,A2,Pesanan!$I$2:$I$87,"Terkirim") -> 4 | G2: =SUMIFS(Retur!$D$2:$D$6,Retur!$C$2:$C$6,A2,Retur!$F$2:$F$6,"Layak jual") -> 0 | H2: 0 | I2: =D2+E2-F2+G2+H2 -> 7 | J2: 5 | K2: 7 | L2: =SUMIFS(Pesanan!$E$2:$E$87,Pesanan!$D$2:$D$87,A2,Pesanan!$I$2:$I$87,"Terkirim",Pesanan!$C$2:$C$87,">="&DATE(2026,9,21),Pesanan!$C$2:$C$87,"<="&DATE(2026,10,20))/30 -> 0.13333333 | M2: =IF(C2="One-off Vintage",0,ROUNDUP(L2*K2+J2,0)) -> 6 | N2: =IF(C2="One-off Vintage","Sourcing per item",IF(I2<=M2,"PERLU RESTOCK","Aman")) -> Aman
A3: V90-TEE-002 | B3: Kaos Washed Boxy | C3: Restockable | D3: 4 | E3: =SUMIFS(Pembelian!$G$2:$G$27,Pembelian!$E$2:$E$27,A3,Pembelian!$C$2:$C$27,">="&DATE(2026,9,1),Pembelian!$C$2:$C$27,"<="&DATE(2026,10,20))-SUMIFS(Pembelian!$J$2:$J$27,Pembelian!$E$2:$E$27,A3,Pembelian!$C$2:$C$27,">="&DATE(2026,9,1),Pembelian!$C$2:$C$27,"<="&DATE(2026,10,20)) -> 6 | F3: =SUMIFS(Pesanan!$E$2:$E$87,Pesanan!$D$2:$D$87,A3,Pesanan!$I$2:$I$87,"Terkirim") -> 6 | G3: =SUMIFS(Retur!$D$2:$D$6,Retur!$C$2:$C$6,A3,Retur!$F$2:$F$6,"Layak jual") -> 1 | H3: 0 | I3: =D3+E3-F3+G3+H3 -> 5 | J3: 6 | K3: 6 | L3: =SUMIFS(Pesanan!$E$2:$E$87,Pesanan!$D$2:$D$87,A3,Pesanan!$I$2:$I$87,"Terkirim",Pesanan!$C$2:$C$87,">="&DATE(2026,9,21),Pesanan!$C$2:$C$87,"<="&DATE(2026,10,20))/30 -> 0.2 | M3: =IF(C3="One-off Vintage",0,ROUNDUP(L3*K3+J3,0)) -> 8 | N3: =IF(C3="One-off Vintage","Sourcing per item",IF(I3<=M3,"PERLU RESTOCK","Aman")) -> PERLU RESTOCK
A4: V90-TEE-003 | B4: Raglan Baseball Tee | C4: Restockable | D4: 2 | E4: =SUMIFS(Pembelian!$G$2:$G$27,Pembelian!$E$2:$E$27,A4,Pembelian!$C$2:$C$27,">="&DATE(2026,9,1),Pembelian!$C$2:$C$27,"<="&DATE(2026,10,20))-SUMIFS(Pembelian!$J$2:$J$27,Pembelian!$E$2:$E$27,A4,Pembelian!$C$2:$C$27,">="&DATE(2026,9,1),Pembelian!$C$2:$C$27,"<="&DATE(2026,10,20)) -> 11 | F4: =SUMIFS(Pesanan!$E$2:$E$87,Pesanan!$D$2:$D$87,A4,Pesanan!$I$2:$I$87,"Terkirim") -> 7 | G4: =SUMIFS(Retur!$D$2:$D$6,Retur!$C$2:$C$6,A4,Retur!$F$2:$F$6,"Layak jual") -> 1 | H4: 0 | I4: =D4+E4-F4+G4+H4 -> 7 | J4: 4 | K4: 8 | L4: =SUMIFS(Pesanan!$E$2:$E$87,Pesanan!$D$2:$D$87,A4,Pesanan!$I$2:$I$87,"Terkirim",Pesanan!$C$2:$C$87,">="&DATE(2026,9,21),Pesanan!$C$2:$C$87,"<="&DATE(2026,10,20))/30 -> 0.23333333 | M4: =IF(C4="One-off Vintage",0,ROUNDUP(L4*K4+J4,0)) -> 6 | N4: =IF(C4="One-off Vintage","Sourcing per item",IF(I4<=M4,"PERLU RESTOCK","Aman")) -> Aman
A5: V90-FLN-001 | B5: Kemeja Flanel Kotak | C5: Restockable | D5: 2 | E5: =SUMIFS(Pembelian!$G$2:$G$27,Pembelian!$E$2:$E$27,A5,Pembelian!$C$2:$C$27,">="&DATE(2026,9,1),Pembelian!$C$2:$C$27,"<="&DATE(2026,10,20))-SUMIFS(Pembelian!$J$2:$J$27,Pembelian!$E$2:$E$27,A5,Pembelian!$C$2:$C$27,">="&DATE(2026,9,1),Pembelian!$C$2:$C$27,"<="&DATE(2026,10,20)) -> 18 | F5: =SUMIFS(Pesanan!$E$2:$E$87,Pesanan!$D$2:$D$87,A5,Pesanan!$I$2:$I$87,"Terkirim") -> 12 | G5: =SUMIFS(Retur!$D$2:$D$6,Retur!$C$2:$C$6,A5,Retur!$F$2:$F$6,"Layak jual") -> 0 | H5: 0 | I5: =D5+E5-F5+G5+H5 -> 8 | J5: 4 | K5: 8 | L5: =SUMIFS(Pesanan!$E$2:$E$87,Pesanan!$D$2:$D$87,A5,Pesanan!$I$2:$I$87,"Terkirim",Pesanan!$C$2:$C$87,">="&DATE(2026,9,21),Pesanan!$C$2:$C$87,"<="&DATE(2026,10,20))/30 -> 0.4 | M5: =IF(C5="One-off Vintage",0,ROUNDUP(L5*K5+J5,0)) -> 8 | N5: =IF(C5="One-off Vintage","Sourcing per item",IF(I5<=M5,"PERLU RESTOCK","Aman")) -> PERLU RESTOCK
A6: V90-DNM-001 | B6: Jaket Denim Oversize | C6: One-off Vintage | D6: 1 | E6: =SUMIFS(Pembelian!$G$2:$G$27,Pembelian!$E$2:$E$27,A6,Pembelian!$C$2:$C$27,">="&DATE(2026,9,1),Pembelian!$C$2:$C$27,"<="&DATE(2026,10,20))-SUMIFS(Pembelian!$J$2:$J$27,Pembelian!$E$2:$E$27,A6,Pembelian!$C$2:$C$27,">="&DATE(2026,9,1),Pembelian!$C$2:$C$27,"<="&DATE(2026,10,20)) -> 0 | F6: =SUMIFS(Pesanan!$E$2:$E$87,Pesanan!$D$2:$D$87,A6,Pesanan!$I$2:$I$87,"Terkirim") -> 1 | G6: =SUMIFS(Retur!$D$2:$D$6,Retur!$C$2:$C$6,A6,Retur!$F$2:$F$6,"Layak jual") -> 0 | H6: 0 | I6: =D6+E6-F6+G6+H6 -> 0 | J6: 0 | K6: 0 | L6: =SUMIFS(Pesanan!$E$2:$E$87,Pesanan!$D$2:$D$87,A6,Pesanan!$I$2:$I$87,"Terkirim",Pesanan!$C$2:$C$87,">="&DATE(2026,9,21),Pesanan!$C$2:$C$87,"<="&DATE(2026,10,20))/30 -> 0.033333333 | M6: =IF(C6="One-off Vintage",0,ROUNDUP(L6*K6+J6,0)) -> 0 | N6: =IF(C6="One-off Vintage","Sourcing per item",IF(I6<=M6,"PERLU RESTOCK","Aman")) -> Sourcing per item
A7: V90-WND-001 | B7: Windbreaker Colorblock | C7: One-off Vintage | D7: 5 | E7: =SUMIFS(Pembelian!$G$2:$G$27,Pembelian!$E$2:$E$27,A7,Pembelian!$C$2:$C$27,">="&DATE(2026,9,1),Pembelian!$C$2:$C$27,"<="&DATE(2026,10,20))-SUMIFS(Pembelian!$J$2:$J$27,Pembelian!$E$2:$E$27,A7,Pembelian!$C$2:$C$27,">="&DATE(2026,9,1),Pembelian!$C$2:$C$27,"<="&DATE(2026,10,20)) -> 0 | F7: =SUMIFS(Pesanan!$E$2:$E$87,Pesanan!$D$2:$D$87,A7,Pesanan!$I$2:$I$87,"Terkirim") -> 4 | G7: =SUMIFS(Retur!$D$2:$D$6,Retur!$C$2:$C$6,A7,Retur!$F$2:$F$6,"Layak jual") -> 0 | H7: 0 | I7: =D7+E7-F7+G7+H7 -> 1 | J7: 0 | K7: 0 | L7: =SUMIFS(Pesanan!$E$2:$E$87,Pesanan!$D$2:$D$87,A7,Pesanan!$I$2:$I$87,"Terkirim",Pesanan!$C$2:$C$87,">="&DATE(2026,9,21),Pesanan!$C$2:$C$87,"<="&DATE(2026,10,20))/30 -> 0.13333333 | M7: =IF(C7="One-off Vintage",0,ROUNDUP(L7*K7+J7,0)) -> 0 | N7: =IF(C7="One-off Vintage","Sourcing per item",IF(I7<=M7,"PERLU RESTOCK","Aman")) -> Sourcing per item
A8: V90-SWT-001 | B8: Crewneck Colorblock | C8: Restockable | D8: 2 | E8: =SUMIFS(Pembelian!$G$2:$G$27,Pembelian!$E$2:$E$27,A8,Pembelian!$C$2:$C$27,">="&DATE(2026,9,1),Pembelian!$C$2:$C$27,"<="&DATE(2026,10,20))-SUMIFS(Pembelian!$J$2:$J$27,Pembelian!$E$2:$E$27,A8,Pembelian!$C$2:$C$27,">="&DATE(2026,9,1),Pembelian!$C$2:$C$27,"<="&DATE(2026,10,20)) -> 15 | F8: =SUMIFS(Pesanan!$E$2:$E$87,Pesanan!$D$2:$D$87,A8,Pesanan!$I$2:$I$87,"Terkirim") -> 10 | G8: =SUMIFS(Retur!$D$2:$D$6,Retur!$C$2:$C$6,A8,Retur!$F$2:$F$6,"Layak jual") -> 0 | H8: 0 | I8: =D8+E8-F8+G8+H8 -> 7 | J8: 3 | K8: 10 | L8: =SUMIFS(Pesanan!$E$2:$E$87,Pesanan!$D$2:$D$87,A8,Pesanan!$I$2:$I$87,"Terkirim",Pesanan!$C$2:$C$87,">="&DATE(2026,9,21),Pesanan!$C$2:$C$87,"<="&DATE(2026,10,20))/30 -> 0.33333333 | M8: =IF(C8="One-off Vintage",0,ROUNDUP(L8*K8+J8,0)) -> 7 | N8: =IF(C8="One-off Vintage","Sourcing per item",IF(I8<=M8,"PERLU RESTOCK","Aman")) -> PERLU RESTOCK
A9: V90-SWT-002 | B9: Sweater Stripe Retro | C9: One-off Vintage | D9: 2 | E9: =SUMIFS(Pembelian!$G$2:$G$27,Pembelian!$E$2:$E$27,A9,Pembelian!$C$2:$C$27,">="&DATE(2026,9,1),Pembelian!$C$2:$C$27,"<="&DATE(2026,10,20))-SUMIFS(Pembelian!$J$2:$J$27,Pembelian!$E$2:$E$27,A9,Pembelian!$C$2:$C$27,">="&DATE(2026,9,1),Pembelian!$C$2:$C$27,"<="&DATE(2026,10,20)) -> 0 | F9: =SUMIFS(Pesanan!$E$2:$E$87,Pesanan!$D$2:$D$87,A9,Pesanan!$I$2:$I$87,"Terkirim") -> 1 | G9: =SUMIFS(Retur!$D$2:$D$6,Retur!$C$2:$C$6,A9,Retur!$F$2:$F$6,"Layak jual") -> 0 | H9: 0 | I9: =D9+E9-F9+G9+H9 -> 1 | J9: 0 | K9: 0 | L9: =SUMIFS(Pesanan!$E$2:$E$87,Pesanan!$D$2:$D$87,A9,Pesanan!$I$2:$I$87,"Terkirim",Pesanan!$C$2:$C$87,">="&DATE(2026,9,21),Pesanan!$C$2:$C$87,"<="&DATE(2026,10,20))/30 -> 0.033333333 | M9: =IF(C9="One-off Vintage",0,ROUNDUP(L9*K9+J9,0)) -> 0 | N9: =IF(C9="One-off Vintage","Sourcing per item",IF(I9<=M9,"PERLU RESTOCK","Aman")) -> Sourcing per item
A10: V90-JNS-001 | B10: Jeans Straight Denim | C10: Restockable | D10: 3 | E10: =SUMIFS(Pembelian!$G$2:$G$27,Pembelian!$E$2:$E$27,A10,Pembelian!$C$2:$C$27,">="&DATE(2026,9,1),Pembelian!$C$2:$C$27,"<="&DATE(2026,10,20))-SUMIFS(Pembelian!$J$2:$J$27,Pembelian!$E$2:$E$27,A10,Pembelian!$C$2:$C$27,">="&DATE(2026,9,1),Pembelian!$C$2:$C$27,"<="&DATE(2026,10,20)) -> 12 | F10: =SUMIFS(Pesanan!$E$2:$E$87,Pesanan!$D$2:$D$87,A10,Pesanan!$I$2:$I$87,"Terkirim") -> 7 | G10: =SUMIFS(Retur!$D$2:$D$6,Retur!$C$2:$C$6,A10,Retur!$F$2:$F$6,"Layak jual") -> 0 | H10: 0 | I10: =D10+E10-F10+G10+H10 -> 8 | J10: 3 | K10: 9 | L10: =SUMIFS(Pesanan!$E$2:$E$87,Pesanan!$D$2:$D$87,A10,Pesanan!$I$2:$I$87,"Terkirim",Pesanan!$C$2:$C$87,">="&DATE(2026,9,21),Pesanan!$C$2:$C$87,"<="&DATE(2026,10,20))/30 -> 0.23333333 | M10: =IF(C10="One-off Vintage",0,ROUNDUP(L10*K10+J10,0)) -> 6 | N10: =IF(C10="One-off Vintage","Sourcing per item",IF(I10<=M10,"PERLU RESTOCK","Aman")) -> Aman
A11: V90-CGO-001 | B11: Celana Cargo 90s | C11: Restockable | D11: 4 | E11: =SUMIFS(Pembelian!$G$2:$G$27,Pembelian!$E$2:$E$27,A11,Pembelian!$C$2:$C$27,">="&DATE(2026,9,1),Pembelian!$C$2:$C$27,"<="&DATE(2026,10,20))-SUMIFS(Pembelian!$J$2:$J$27,Pembelian!$E$2:$E$27,A11,Pembelian!$C$2:$C$27,">="&DATE(2026,9,1),Pembelian!$C$2:$C$27,"<="&DATE(2026,10,20)) -> 13 | F11: =SUMIFS(Pesanan!$E$2:$E$87,Pesanan!$D$2:$D$87,A11,Pesanan!$I$2:$I$87,"Terkirim") -> 12 | G11: =SUMIFS(Retur!$D$2:$D$6,Retur!$C$2:$C$6,A11,Retur!$F$2:$F$6,"Layak jual") -> 0 | H11: 0 | I11: =D11+E11-F11+G11+H11 -> 5 | J11: 4 | K11: 7 | L11: =SUMIFS(Pesanan!$E$2:$E$87,Pesanan!$D$2:$D$87,A11,Pesanan!$I$2:$I$87,"Terkirim",Pesanan!$C$2:$C$87,">="&DATE(2026,9,21),Pesanan!$C$2:$C$87,"<="&DATE(2026,10,20))/30 -> 0.4 | M11: =IF(C11="One-off Vintage",0,ROUNDUP(L11*K11+J11,0)) -> 7 | N11: =IF(C11="One-off Vintage","Sourcing per item",IF(I11<=M11,"PERLU RESTOCK","Aman")) -> PERLU RESTOCK
A12: V90-VST-001 | B12: Vest Knit Retro | C12: One-off Vintage | D12: 1 | E12: =SUMIFS(Pembelian!$G$2:$G$27,Pembelian!$E$2:$E$27,A12,Pembelian!$C$2:$C$27,">="&DATE(2026,9,1),Pembelian!$C$2:$C$27,"<="&DATE(2026,10,20))-SUMIFS(Pembelian!$J$2:$J$27,Pembelian!$E$2:$E$27,A12,Pembelian!$C$2:$C$27,">="&DATE(2026,9,1),Pembelian!$C$2:$C$27,"<="&DATE(2026,10,20)) -> 0 | F12: =SUMIFS(Pesanan!$E$2:$E$87,Pesanan!$D$2:$D$87,A12,Pesanan!$I$2:$I$87,"Terkirim") -> 0 | G12: =SUMIFS(Retur!$D$2:$D$6,Retur!$C$2:$C$6,A12,Retur!$F$2:$F$6,"Layak jual") -> 0 | H12: 0 | I12: =D12+E12-F12+G12+H12 -> 1 | J12: 0 | K12: 0 | L12: =SUMIFS(Pesanan!$E$2:$E$87,Pesanan!$D$2:$D$87,A12,Pesanan!$I$2:$I$87,"Terkirim",Pesanan!$C$2:$C$87,">="&DATE(2026,9,21),Pesanan!$C$2:$C$87,"<="&DATE(2026,10,20))/30 -> 0 | M12: =IF(C12="One-off Vintage",0,ROUNDUP(L12*K12+J12,0)) -> 0 | N12: =IF(C12="One-off Vintage","Sourcing per item",IF(I12<=M12,"PERLU RESTOCK","Aman")) -> Sourcing per item
A13: V90-HDY-001 | B13: Hoodie Zip Vintage | C13: Restockable | D13: 4 | E13: =SUMIFS(Pembelian!$G$2:$G$27,Pembelian!$E$2:$E$27,A13,Pembelian!$C$2:$C$27,">="&DATE(2026,9,1),Pembelian!$C$2:$C$27,"<="&DATE(2026,10,20))-SUMIFS(Pembelian!$J$2:$J$27,Pembelian!$E$2:$E$27,A13,Pembelian!$C$2:$C$27,">="&DATE(2026,9,1),Pembelian!$C$2:$C$27,"<="&DATE(2026,10,20)) -> 4 | F13: =SUMIFS(Pesanan!$E$2:$E$87,Pesanan!$D$2:$D$87,A13,Pesanan!$I$2:$I$87,"Terkirim") -> 2 | G13: =SUMIFS(Retur!$D$2:$D$6,Retur!$C$2:$C$6,A13,Retur!$F$2:$F$6,"Layak jual") -> 0 | H13: 0 | I13: =D13+E13-F13+G13+H13 -> 6 | J13: 3 | K13: 10 | L13: =SUMIFS(Pesanan!$E$2:$E$87,Pesanan!$D$2:$D$87,A13,Pesanan!$I$2:$I$87,"Terkirim",Pesanan!$C$2:$C$87,">="&DATE(2026,9,21),Pesanan!$C$2:$C$87,"<="&DATE(2026,10,20))/30 -> 0.066666667 | M13: =IF(C13="One-off Vintage",0,ROUNDUP(L13*K13+J13,0)) -> 4 | N13: =IF(C13="One-off Vintage","Sourcing per item",IF(I13<=M13,"PERLU RESTOCK","Aman")) -> Aman
... A16: V90-TRK-001 | B16: Track Jacket Retro | C16: Restockable | D16: 4 | E16: =SUMIFS(Pembelian!$G$2:$G$27,Pembelian!$E$2:$E$27,A16,Pembelian!$C$2:$C$27,">="&DATE(2026,9,1),Pembelian!$C$2:$C$27,"<="&DATE(2026,10,20))-SUMIFS(Pembelian!$J$2:$J$27,Pembelian!$E$2:$E$27,A16,Pembelian!$C$2:$C$27,">="&DATE(2026,9,1),Pembelian!$C$2:$C$27,"<="&DATE(2026,10,20)) -> 6 | F16: =SUMIFS(Pesanan!$E$2:$E$87,Pesanan!$D$2:$D$87,A16,Pesanan!$I$2:$I$87,"Terkirim") -> 3 | G16: =SUMIFS(Retur!$D$2:$D$6,Retur!$C$2:$C$6,A16,Retur!$F$2:$F$6,"Layak jual") -> 0 | H16: 0 | I16: =D16+E16-F16+G16+H16 -> 7 | J16: 3 | K16: 10 | L16: =SUMIFS(Pesanan!$E$2:$E$87,Pesanan!$D$2:$D$87,A16,Pesanan!$I$2:$I$87,"Terkirim",Pesanan!$C$2:$C$87,">="&DATE(2026,9,21),Pesanan!$C$2:$C$87,"<="&DATE(2026,10,20))/30 -> 0.1 | M16: =IF(C16="One-off Vintage",0,ROUNDUP(L16*K16+J16,0)) -> 4 | N16: =IF(C16="One-off Vintage","Sourcing per item",IF(I16<=M16,"PERLU RESTOCK","Aman")) -> Aman
